#!/usr/bin/env python3
"""
Unit tests for validate_otel.py - Testing try-except blocks
Tests error handling, then we'll remove it to let it crash
"""

import asyncio
import pytest
import json
from unittest.mock import patch, MagicMock, AsyncMock
from pathlib import Path

from validate_otel import OTELValidator


class TestValidateOTELCrash:
    """Test suite for try-except blocks in validate_otel.py"""
    
    @pytest.fixture
    def validator(self):
        """Create validator instance"""
        return OTELValidator()
    
    @pytest.mark.asyncio
    async def test_run_validation_test_exception(self, validator):
        """Test _run_validation_test handles exceptions"""
        # Create a failing validator
        async def failing_validator():
            raise ValueError("Test validation error")
        
        # Should catch and record the error
        await validator._run_validation_test("Test Component", failing_validator)
        
        assert len(validator.validation_results) == 1
        assert validator.validation_results[0]["success"] is False
        assert validator.validation_results[0]["error"] == "Test validation error"
    
    @pytest.mark.asyncio
    async def test_validate_cns_status_subprocess_error(self, validator):
        """Test CNS status validation with subprocess errors"""
        with patch('asyncio.create_subprocess_exec') as mock_exec:
            mock_exec.side_effect = FileNotFoundError("cns_status.py not found")
            
            result = await validator._validate_cns_status()
            
            assert result["success"] is False
            assert "CNS status validation error:" in result["issues"][0]
    
    @pytest.mark.asyncio
    async def test_validate_cns_status_json_decode_error(self, validator):
        """Test CNS status with invalid JSON output"""
        with patch('asyncio.create_subprocess_exec') as mock_exec:
            mock_process = AsyncMock()
            mock_process.returncode = 0
            mock_process.communicate = AsyncMock(return_value=(b'Not valid JSON', b''))
            mock_exec.return_value = mock_process
            
            result = await validator._validate_cns_status()
            
            assert result["success"] is False
            assert "CNS status output is not valid JSON" in result["issues"]
    
    @pytest.mark.asyncio
    async def test_validate_owl_compiler_exception(self, validator):
        """Test OWL compiler validation with exceptions"""
        with patch('asyncio.create_subprocess_exec') as mock_exec:
            mock_exec.side_effect = PermissionError("Access denied")
            
            result = await validator._validate_owl_compiler()
            
            assert result["success"] is False
            assert "OWL compiler validation error:" in result["issues"][0]
    
    @pytest.mark.asyncio
    async def test_validate_benchmark_parse_error(self, validator):
        """Test benchmark validation with parsing errors"""
        with patch('asyncio.create_subprocess_exec') as mock_exec:
            mock_process = AsyncMock()
            mock_process.returncode = 0
            mock_process.communicate = AsyncMock(return_value=(b'Performance Score: invalid', b''))
            mock_exec.return_value = mock_process
            
            result = await validator._validate_benchmark_system()
            
            # Should handle parse errors
            assert "Could not parse performance score" in result["issues"]
    
    @pytest.mark.asyncio
    async def test_validate_performance_monitor_timeout(self, validator):
        """Test performance monitor with timeout"""
        with patch('asyncio.create_subprocess_exec') as mock_exec:
            mock_process = AsyncMock()
            # Simulate timeout
            with patch('asyncio.wait_for') as mock_wait:
                mock_wait.side_effect = asyncio.TimeoutError()
                mock_exec.return_value = mock_process
                
                result = await validator._validate_performance_monitor()
                
                assert result["success"] is False
                assert "Performance monitor validation timed out" in result["issues"]
    
    @pytest.mark.asyncio
    async def test_validate_generated_code_exception(self, validator):
        """Test generated code validation with exceptions"""
        with patch('pathlib.Path.exists') as mock_exists:
            mock_exists.return_value = True
            
            with patch('asyncio.create_subprocess_exec') as mock_exec:
                mock_exec.side_effect = OSError("Binary execution failed")
                
                result = await validator._validate_generated_code()
                
                assert result["success"] is False
                assert "Generated code validation error:" in result["issues"][0]
    
    @pytest.mark.asyncio
    async def test_validate_otel_integration_exception(self, validator):
        """Test OTEL integration validation with import errors"""
        with patch('opentelemetry.metrics.get_meter_provider') as mock_provider:
            mock_provider.side_effect = ImportError("OTEL not installed")
            
            result = await validator._validate_otel_integration()
            
            assert result["success"] is False
            assert "OTEL integration validation error:" in result["issues"][0]
    
    @pytest.mark.asyncio
    async def test_main_exception_handling(self):
        """Test main function exception handling"""
        with patch('validate_otel.OTELValidator.run_comprehensive_validation') as mock_run:
            mock_run.side_effect = RuntimeError("Validation system error")
            
            # Should handle the exception
            with pytest.raises(RuntimeError):
                await main()


if __name__ == "__main__":
    pytest.main([__file__, "-v"])